retrying ...1secs
retrying ...1secs
retrying ...1secs
retrying ...1secs
retrying ...1secs
retrying ...1secs
retrying ...1secs
retrying ...1secs
retrying ...1secs
retrying ...1secs
retrying ...1secs
retrying ...1secs
retrying ...1secs
retrying ...1secs
retrying ...2secs
retrying ...1secs
retrying ...1secs
retrying ...2secs
4.05 horas
Traceback (most recent call last):
  File "Gerador_Json.py", line 93, in <module>
    arquivo3 = json.loads(open("dados.json", "r").read())
  File "/usr/lib/python3.7/json/__init__.py", line 348, in loads
    return _default_decoder.decode(s)
  File "/usr/lib/python3.7/json/decoder.py", line 337, in decode
    obj, end = self.raw_decode(s, idx=_w(s, 0).end())
  File "/usr/lib/python3.7/json/decoder.py", line 353, in raw_decode
    obj, end = self.scan_once(s, idx)
json.decoder.JSONDecodeError: Expecting ':' delimiter: line 1 column 141294533 (char 141294532)



1.04 horas
Traceback (most recent call last):
  File "Gerador_Json.py", line 93, in <module>
    arquivo3 = json.loads(open("dados.json", "r").read())
  File "/usr/lib/python3.7/json/__init__.py", line 348, in loads
    return _default_decoder.decode(s)
  File "/usr/lib/python3.7/json/decoder.py", line 337, in decode
    obj, end = self.raw_decode(s, idx=_w(s, 0).end())
  File "/usr/lib/python3.7/json/decoder.py", line 353, in raw_decode
    obj, end = self.scan_once(s, idx)
json.decoder.JSONDecodeError: Expecting ':' delimiter: line 1 column 10264677 (char 10264676)


------------------------------------------------------------------------------
Traceback (most recent call last):
  File "/usr/lib/python3.7/site-packages/urllib3/connection.py", line 157, in _new_conn
    (self._dns_host, self.port), self.timeout, **extra_kw
  File "/usr/lib/python3.7/site-packages/urllib3/util/connection.py", line 61, in create_connection
    for res in socket.getaddrinfo(host, port, family, socket.SOCK_STREAM):
  File "/usr/lib/python3.7/socket.py", line 748, in getaddrinfo
    for res in _socket.getaddrinfo(host, port, family, type, proto, flags):
socket.gaierror: [Errno -2] Name or service not known

During handling of the above exception, another exception occurred:

Traceback (most recent call last):
  File "/usr/lib/python3.7/site-packages/urllib3/connectionpool.py", line 672, in urlopen
    chunked=chunked,
  File "/usr/lib/python3.7/site-packages/urllib3/connectionpool.py", line 376, in _make_request
    self._validate_conn(conn)
  File "/usr/lib/python3.7/site-packages/urllib3/connectionpool.py", line 994, in _validate_conn
    conn.connect()
  File "/usr/lib/python3.7/site-packages/urllib3/connection.py", line 334, in connect
    conn = self._new_conn()
  File "/usr/lib/python3.7/site-packages/urllib3/connection.py", line 169, in _new_conn
    self, "Failed to establish a new connection: %s" % e
urllib3.exceptions.NewConnectionError: <urllib3.connection.VerifiedHTTPSConnection object at 0x7f9531392450>: Failed to establish a new connection: [Errno -2] Name or service not known

During handling of the above exception, another exception occurred:

Traceback (most recent call last):
  File "/usr/lib/python3.7/site-packages/requests/adapters.py", line 449, in send
    timeout=timeout
  File "/usr/lib/python3.7/site-packages/urllib3/connectionpool.py", line 720, in urlopen
    method, url, error=e, _pool=self, _stacktrace=sys.exc_info()[2]
  File "/usr/lib/python3.7/site-packages/urllib3/util/retry.py", line 436, in increment
    raise MaxRetryError(_pool, url, error or ResponseError(cause))
urllib3.exceptions.MaxRetryError: HTTPSConnectionPool(host='api.spotify.com', port=443): Max retries exceeded with url: /v1/albums/65WBpuJcunfKVGft4JwNeI (Caused by NewConnectionError('<urllib3.connection.VerifiedHTTPSConnection object at 0x7f9531392450>: Failed to establish a new connection: [Errno -2] Name or service not known'))

During handling of the above exception, another exception occurred:

Traceback (most recent call last):
  File "Gerador_Json.py", line 86, in <module>
    search(cantor)
  File "Gerador_Json.py", line 75, in search
    info_artist(artist['id'])
  File "Gerador_Json.py", line 31, in info_artist
    show_artist_albums(id)
  File "Gerador_Json.py", line 47, in show_artist_albums
    info_album(album['id'])
  File "Gerador_Json.py", line 54, in info_album
    result_json2 = sp.album(id)
  File "/usr/lib/python3.7/site-packages/spotipy/client.py", line 303, in album
    return self._get('albums/' + trid)
  File "/usr/lib/python3.7/site-packages/spotipy/client.py", line 146, in _get
    return self._internal_call('GET', url, payload, kwargs)
  File "/usr/lib/python3.7/site-packages/spotipy/client.py", line 108, in _internal_call
    r = self._session.request(method, url, headers=headers, proxies=self.proxies, **args)
  File "/usr/lib/python3.7/site-packages/requests/sessions.py", line 533, in request
    resp = self.send(prep, **send_kwargs)
  File "/usr/lib/python3.7/site-packages/requests/sessions.py", line 646, in send
    r = adapter.send(request, **kwargs)
  File "/usr/lib/python3.7/site-packages/requests/adapters.py", line 516, in send
    raise ConnectionError(e, request=request)
requests.exceptions.ConnectionError: HTTPSConnectionPool(host='api.spotify.com', port=443): Max retries exceeded with url: /v1/albums/65WBpuJcunfKVGft4JwNeI (Caused by NewConnectionError('<urllib3.connection.VerifiedHTTPSConnection object at 0x7f9531392450>: Failed to establish a new connection: [Errno -2] Name or service not known'))

